Workbook
Name Slicer_Category: #N/A
Name Slicer_Delivery_Status: #N/A
Name Slicer_Region: #N/A
Name Slicer_Supplier: #N/A
Name Slicer_Transport_Mode: #N/A
Name Slicer_Warehouse: #N/A

Sheet Sheet1
A1: Order ID | B1: Order Date | C1: Customer / Contact | D1: Product | E1: Category | F1: Supplier | G1: Origin | H1: Destination | I1: Region | J1: Warehouse | K1: Transport Mode | L1: Quantity | M1: Unit Cost | N1: Order Value | O1: Current Stock | P1: Reorder Level | Q1: Lead Time (Days) | R1: Promised Date | S1: Delivery Date | T1: Delivery Status
A2: SC-1001 | B2: 46244 | C2: Nguyen Minh Anh | D2: Barcode Scanner | E2: Warehouse Equipment | F2: Pacific Source | G2: Malaysia | H2: Vietnam | I2: Vietnam | J2: Ho Chi Minh DC | K2: Air | L2: 32 | M2: 180 | N2: 5760 | O2: 346 | P2: 50 | Q2: 14 | R2: 46258 | S2: 46260 | T2: Delayed
A3: SC-1002 | B3: 46209 | C3: Tran Quang Huy | D3: Conveyor Belt | E3: Material Handling | F3: VinaTech Supplies | G3: Vietnam | H3: Singapore | I3: Singapore | J3: Ho Chi Minh DC | K3: Sea | L3: 236 | M3: 420 | N3: 99120 | O3: 258 | P3: 75 | Q3: 12 | R3: 46221 | S3: 46221 | T3: On Time
A4: SC-1003 | B4: 46239 | C4: Le Thi Mai | D4: Packaging Box | E4: Packaging | F4: Mekong Distribution | G4: Indonesia | H4: Thailand | I4: Thailand | J4: Bangkok DC | K4: Air | L4: 386 | M4: 4.5 | N4: 1737 | O4: 142 | P4: 150 | Q4: 15 | R4: 46254 | S4: 46259 | T4: Delayed
A5: SC-1004 | B5: 46204 | C5: Pham Hoang Nam | D5: Safety Gloves | E5: Safety | F5: Korea Industrial Co. | G5: South Korea | H5: Malaysia | I5: Malaysia | J5: Ho Chi Minh DC | K5: Road | L5: 377 | M5: 12 | N5: 4524 | O5: 390 | P5: 75 | Q5: 8 | R5: 46212 | S5: 46212 | T5: On Time
A6: SC-1005 | B6: 46209 | C6: Arjun Mehta | D6: Handheld Terminal | E6: Electronics | F6: IndoTrade Solutions | G6: South Korea | H6: Malaysia | I6: Malaysia | J6: Hanoi DC | K6: Road | L6: 69 | M6: 320 | N6: 22080 | O6: 274 | P6: 125 | Q6: 4 | R6: 46213 | S6: 46214 | T6: Delayed
A7: SC-1006 | B7: 46209 | C7: Priya Nair | D7: Safety Helmet | E7: Safety | F7: Dragon Supply Co. | G7: South Korea | H7: Malaysia | I7: Malaysia | J7: Kuala Lumpur DC | K7: Air | L7: 170 | M7: 18 | N7: 3060 | O7: 23 | P7: 50 | Q7: 13 | R7: 46222 | S7: 46222 | T7: On Time
A8: SC-1007 | B8: 46222 | C8: Rahul Sharma | D8: Barcode Scanner | E8: Warehouse Equipment | F8: Siam Components | G8: India | H8: Vietnam | I8: Vietnam | J8: Singapore Hub | K8: Rail | L8: 457 | M8: 180 | N8: 82260 | O8: 325 | P8: 125 | Q8: 8 | R8: 46230 | S8: 46230 | T8: On Time
A9: SC-1008 | B9: 46227 | C9: Ananya Iyer | D9: RFID Labels | E9: Technology | F9: Pacific Source | G9: India | H9: Vietnam | I9: Vietnam | J9: Mumbai DC | K9: Air | L9: 127 | M9: 0.8 | N9: 101.6 | O9: 83 | P9: 75 | Q9: 10 | R9: 46237 | S9: 46238 | T9: Delayed
A10: SC-1009 | B10: 46221 | C10: Tan Wei Ming | D10: Safety Helmet | E10: Safety | F10: IndoTrade Solutions | G10: Vietnam | H10: Singapore | I10: Singapore | J10: Hanoi DC | K10: Air | L10: 132 | M10: 18 | N10: 2376 | O10: 205 | P10: 100 | Q10: 7 | R10: 46228 | S10: 46228 | T10: On Time
A11: SC-1010 | B11: 46217 | C11: Lim Jia Hui | D11: Conveyor Belt | E11: Material Handling | F11: IndoTrade Solutions | G11: Malaysia | H11: Vietnam | I11: Vietnam | J11: Bangkok DC | K11: Rail | L11: 468 | M11: 420 | N11: 196560 | O11: 73 | P11: 125 | Q11: 7 | R11: 46224 | S11: 46224 | T11: On Time
A12: SC-1011 | B12: 46219 | C12: Siti Nur Aisyah | D12: Safety Helmet | E12: Safety | F12: Pacific Source | G12: India | H12: Singapore | I12: Singapore | J12: Mumbai DC | K12: Rail | L12: 295 | M12: 18 | N12: 5310 | O12: 185 | P12: 125 | Q12: 6 | R12: 46225 | S12: 46225 | T12: On Time
A13: SC-1012 | B13: 46236 | C13: Ahmad Faiz | D13: Stretch Film | E13: Packaging | F13: VinaTech Supplies | G13: India | H13: Vietnam | I13: Vietnam | J13: Kuala Lumpur DC | K13: Air | L13: 66 | M13: 15 | N13: 990 | O13: 348 | P13: 75 | Q13: 9 | R13: 46245 | S13: 46247 | T13: Delayed
... A31: SC-1030 | B31: 46242 | C31: Dimas Pratama | D31: Barcode Scanner | E31: Warehouse Equipment | F31: Siam Components | G31: Indonesia | H31: Thailand | I31: Thailand | J31: Mumbai DC | K31: Sea | L31: 365 | M31: 180 | N31: 65700 | O31: 296 | P31: 75 | Q31: 12 | R31: 46254 | S31: 46254 | T31: On Time

Sheet Clean Data
A1: Order ID | B1: Order Date | C1: Customer / Contact | D1: Product | E1: Category | F1: Supplier | G1: Origin | H1: Destination | I1: Region | J1: Warehouse | K1: Transport Mode | L1: Quantity | M1: Unit Cost | N1: Order Value | O1: Current Stock | P1: Reorder Level | Q1: Lead Time (Days) | R1: Promised Date | S1: Delivery Date | T1: Delivery Status | U1: Delivery Delay Days | V1: On-Time Flag | W1: Delay Flag | X1: Stock Status | Y1: Stock-out Flag | Z1: Low Stock Flag | AA1: Healthy Stock Flag | AB1: Supplier On-Time % | AC1: Delivery Cycle Days | AD1: Stock Variance
A2: SC-1001 | B2: 46244 | C2: Nguyen Minh Anh | D2: Barcode Scanner | E2: Warehouse Equipment | F2: Pacific Source | G2: Malaysia | H2: Vietnam | I2: Vietnam | J2: Ho Chi Minh DC | K2: Air | L2: 32 | M2: 180 | N2: 5760 | O2: 346 | P2: 50 | Q2: 14 | R2: 46258 | S2: 46260 | T2: Delayed | U2: =VSCN_Clean[[#This Row],[Delivery Date]]-VSCN_Clean[[#This Row],[Promised Date]] -> 2 | V2: =--(VSCN_Clean[[#This Row],[Delivery Date]]<=VSCN_Clean[[#This Row],[Promised Date]]) -> 0 | W2: =--(VSCN_Clean[[#This Row],[Delivery Date]]>VSCN_Clean[[#This Row],[Promised Date]]) -> 1 | X2: =IF(VSCN_Clean[[#This Row],[Current Stock]]<=0,"Stock-out",IF(VSCN_Clean[[#This Row],[Current Stock]]<VSCN_Clean[[#This Row],[Reorder Level]],"Low Stock","Healthy")) -> Healthy | Y2: =--(VSCN_Clean[[#This Row],[Current Stock]]<=0) -> 0 | Z2: =--(AND(VSCN_Clean[[#This Row],[Current Stock]]>0,VSCN_Clean[[#This Row],[Current Stock]]<VSCN_Clean[[#This Row],[Reorder Level]])) -> 0 | AA2: =--(VSCN_Clean[[#This Row],[Current Stock]]>=VSCN_Clean[[#This Row],[Reorder Level]]) -> 1 | AB2: =IFERROR(COUNTIFS(VSCN_Clean[Supplier],VSCN_Clean[[#This Row],[Supplier]],VSCN_Clean[On-Time Flag],1)/COUNTIF(VSCN_Clean[Supplier],VSCN_Clean[[#This Row],[Supplier]]),0) -> 0.6 | AC2: =VSCN_Clean[[#This Row],[Delivery Date]]-VSCN_Clean[[#This Row],[Order Date]] -> 16 | AD2: =VSCN_Clean[[#This Row],[Current Stock]]-VSCN_Clean[[#This Row],[Reorder Level]] -> 296
A3: SC-1002 | B3: 46209 | C3: Tran Quang Huy | D3: Conveyor Belt | E3: Material Handling | F3: VinaTech Supplies | G3: Vietnam | H3: Singapore | I3: Singapore | J3: Ho Chi Minh DC | K3: Sea | L3: 236 | M3: 420 | N3: 99120 | O3: 258 | P3: 75 | Q3: 12 | R3: 46221 | S3: 46221 | T3: On Time | U3: =VSCN_Clean[[#This Row],[Delivery Date]]-VSCN_Clean[[#This Row],[Promised Date]] -> 0 | V3: =--(VSCN_Clean[[#This Row],[Delivery Date]]<=VSCN_Clean[[#This Row],[Promised Date]]) -> 1 | W3: =--(VSCN_Clean[[#This Row],[Delivery Date]]>VSCN_Clean[[#This Row],[Promised Date]]) -> 0 | X3: =IF(VSCN_Clean[[#This Row],[Current Stock]]<=0,"Stock-out",IF(VSCN_Clean[[#This Row],[Current Stock]]<VSCN_Clean[[#This Row],[Reorder Level]],"Low Stock","Healthy")) -> Healthy | Y3: =--(VSCN_Clean[[#This Row],[Current Stock]]<=0) -> 0 | Z3: =--(AND(VSCN_Clean[[#This Row],[Current Stock]]>0,VSCN_Clean[[#This Row],[Current Stock]]<VSCN_Clean[[#This Row],[Reorder Level]])) -> 0 | AA3: =--(VSCN_Clean[[#This Row],[Current Stock]]>=VSCN_Clean[[#This Row],[Reorder Level]]) -> 1 | AB3: =IFERROR(COUNTIFS(VSCN_Clean[Supplier],VSCN_Clean[[#This Row],[Supplier]],VSCN_Clean[On-Time Flag],1)/COUNTIF(VSCN_Clean[Supplier],VSCN_Clean[[#This Row],[Supplier]]),0) -> 0.25 | AC3: =VSCN_Clean[[#This Row],[Delivery Date]]-VSCN_Clean[[#This Row],[Order Date]] -> 12 | AD3: =VSCN_Clean[[#This Row],[Current Stock]]-VSCN_Clean[[#This Row],[Reorder Level]] -> 183
A4: SC-1003 | B4: 46239 | C4: Le Thi Mai | D4: Packaging Box | E4: Packaging | F4: Mekong Distribution | G4: Indonesia | H4: Thailand | I4: Thailand | J4: Bangkok DC | K4: Air | L4: 386 | M4: 4.5 | N4: 1737 | O4: 142 | P4: 150 | Q4: 15 | R4: 46254 | S4: 46259 | T4: Delayed | U4: =VSCN_Clean[[#This Row],[Delivery Date]]-VSCN_Clean[[#This Row],[Promised Date]] -> 5 | V4: =--(VSCN_Clean[[#This Row],[Delivery Date]]<=VSCN_Clean[[#This Row],[Promised Date]]) -> 0 | W4: =--(VSCN_Clean[[#This Row],[Delivery Date]]>VSCN_Clean[[#This Row],[Promised Date]]) -> 1 | X4: =IF(VSCN_Clean[[#This Row],[Current Stock]]<=0,"Stock-out",IF(VSCN_Clean[[#This Row],[Current Stock]]<VSCN_Clean[[#This Row],[Reorder Level]],"Low Stock","Healthy")) -> Low Stock | Y4: =--(VSCN_Clean[[#This Row],[Current Stock]]<=0) -> 0 | Z4: =--(AND(VSCN_Clean[[#This Row],[Current Stock]]>0,VSCN_Clean[[#This Row],[Current Stock]]<VSCN_Clean[[#This Row],[Reorder Level]])) -> 1 | AA4: =--(VSCN_Clean[[#This Row],[Current Stock]]>=VSCN_Clean[[#This Row],[Reorder Level]]) -> 0 | AB4: =IFERROR(COUNTIFS(VSCN_Clean[Supplier],VSCN_Clean[[#This Row],[Supplier]],VSCN_Clean[On-Time Flag],1)/COUNTIF(VSCN_Clean[Supplier],VSCN_Clean[[#This Row],[Supplier]]),0) -> 0 | AC4: =VSCN_Clean[[#This Row],[Delivery Date]]-VSCN_Clean[[#This Row],[Order Date]] -> 20 | AD4: =VSCN_Clean[[#This Row],[Current Stock]]-VSCN_Clean[[#This Row],[Reorder Level]] -> -8
A5: SC-1004 | B5: 46204 | C5: Pham Hoang Nam | D5: Safety Gloves | E5: Safety | F5: Korea Industrial Co. | G5: South Korea | H5: Malaysia | I5: Malaysia | J5: Ho Chi Minh DC | K5: Road | L5: 377 | M5: 12 | N5: 4524 | O5: 390 | P5: 75 | Q5: 8 | R5: 46212 | S5: 46212 | T5: On Time | U5: =VSCN_Clean[[#This Row],[Delivery Date]]-VSCN_Clean[[#This Row],[Promised Date]] -> 0 | V5: =--(VSCN_Clean[[#This Row],[Delivery Date]]<=VSCN_Clean[[#This Row],[Promised Date]]) -> 1 | W5: =--(VSCN_Clean[[#This Row],[Delivery Date]]>VSCN_Clean[[#This Row],[Promised Date]]) -> 0 | X5: =IF(VSCN_Clean[[#This Row],[Current Stock]]<=0,"Stock-out",IF(VSCN_Clean[[#This Row],[Current Stock]]<VSCN_Clean[[#This Row],[Reorder Level]],"Low Stock","Healthy")) -> Healthy | Y5: =--(VSCN_Clean[[#This Row],[Current Stock]]<=0) -> 0 | Z5: =--(AND(VSCN_Clean[[#This Row],[Current Stock]]>0,VSCN_Clean[[#This Row],[Current Stock]]<VSCN_Clean[[#This Row],[Reorder Level]])) -> 0 | AA5: =--(VSCN_Clean[[#This Row],[Current Stock]]>=VSCN_Clean[[#This Row],[Reorder Level]]) -> 1 | AB5: =IFERROR(COUNTIFS(VSCN_Clean[Supplier],VSCN_Clean[[#This Row],[Supplier]],VSCN_Clean[On-Time Flag],1)/COUNTIF(VSCN_Clean[Supplier],VSCN_Clean[[#This Row],[Supplier]]),0) -> 0.33333333 | AC5: =VSCN_Clean[[#This Row],[Delivery Date]]-VSCN_Clean[[#This Row],[Order Date]] -> 8 | AD5: =VSCN_Clean[[#This Row],[Current Stock]]-VSCN_Clean[[#This Row],[Reorder Level]] -> 315
A6: SC-1005 | B6: 46209 | C6: Arjun Mehta | D6: Handheld Terminal | E6: Electronics | F6: IndoTrade Solutions | G6: South Korea | H6: Malaysia | I6: Malaysia | J6: Hanoi DC | K6: Road | L6: 69 | M6: 320 | N6: 22080 | O6: 274 | P6: 125 | Q6: 4 | R6: 46213 | S6: 46214 | T6: Delayed | U6: =VSCN_Clean[[#This Row],[Delivery Date]]-VSCN_Clean[[#This Row],[Promised Date]] -> 1 | V6: =--(VSCN_Clean[[#This Row],[Delivery Date]]<=VSCN_Clean[[#This Row],[Promised Date]]) -> 0 | W6: =--(VSCN_Clean[[#This Row],[Delivery Date]]>VSCN_Clean[[#This Row],[Promised Date]]) -> 1 | X6: =IF(VSCN_Clean[[#This Row],[Current Stock]]<=0,"Stock-out",IF(VSCN_Clean[[#This Row],[Current Stock]]<VSCN_Clean[[#This Row],[Reorder Level]],"Low Stock","Healthy")) -> Healthy | Y6: =--(VSCN_Clean[[#This Row],[Current Stock]]<=0) -> 0 | Z6: =--(AND(VSCN_Clean[[#This Row],[Current Stock]]>0,VSCN_Clean[[#This Row],[Current Stock]]<VSCN_Clean[[#This Row],[Reorder Level]])) -> 0 | AA6: =--(VSCN_Clean[[#This Row],[Current Stock]]>=VSCN_Clean[[#This Row],[Reorder Level]]) -> 1 | AB6: =IFERROR(COUNTIFS(VSCN_Clean[Supplier],VSCN_Clean[[#This Row],[Supplier]],VSCN_Clean[On-Time Flag],1)/COUNTIF(VSCN_Clean[Supplier],VSCN_Clean[[#This Row],[Supplier]]),0) -> 0.75 | AC6: =VSCN_Clean[[#This Row],[Delivery Date]]-VSCN_Clean[[#This Row],[Order Date]] -> 5 | AD6: =VSCN_Clean[[#This Row],[Current Stock]]-VSCN_Clean[[#This Row],[Reorder Level]] -> 149
A7: SC-1006 | B7: 46209 | C7: Priya Nair | D7: Safety Helmet | E7: Safety | F7: Dragon Supply Co. | G7: South Korea | H7: Malaysia | I7: Malaysia | J7: Kuala Lumpur DC | K7: Air | L7: 170 | M7: 18 | N7: 3060 | O7: 23 | P7: 50 | Q7: 13 | R7: 46222 | S7: 46222 | T7: On Time | U7: =VSCN_Clean[[#This Row],[Delivery Date]]-VSCN_Clean[[#This Row],[Promised Date]] -> 0 | V7: =--(VSCN_Clean[[#This Row],[Delivery Date]]<=VSCN_Clean[[#This Row],[Promised Date]]) -> 1 | W7: =--(VSCN_Clean[[#This Row],[Delivery Date]]>VSCN_Clean[[#This Row],[Promised Date]]) -> 0 | X7: =IF(VSCN_Clean[[#This Row],[Current Stock]]<=0,"Stock-out",IF(VSCN_Clean[[#This Row],[Current Stock]]<VSCN_Clean[[#This Row],[Reorder Level]],"Low Stock","Healthy")) -> Low Stock | Y7: =--(VSCN_Clean[[#This Row],[Current Stock]]<=0) -> 0 | Z7: =--(AND(VSCN_Clean[[#This Row],[Current Stock]]>0,VSCN_Clean[[#This Row],[Current Stock]]<VSCN_Clean[[#This Row],[Reorder Level]])) -> 1 | AA7: =--(VSCN_Clean[[#This Row],[Current Stock]]>=VSCN_Clean[[#This Row],[Reorder Level]]) -> 0 | AB7: =IFERROR(COUNTIFS(VSCN_Clean[Supplier],VSCN_Clean[[#This Row],[Supplier]],VSCN_Clean[On-Time Flag],1)/COUNTIF(VSCN_Clean[Supplier],VSCN_Clean[[#This Row],[Supplier]]),0) -> 1 | AC7: =VSCN_Clean[[#This Row],[Delivery Date]]-VSCN_Clean[[#This Row],[Order Date]] -> 13 | AD7: =VSCN_Clean[[#This Row],[Current Stock]]-VSCN_Clean[[#This Row],[Reorder Level]] -> -27
A8: SC-1007 | B8: 46222 | C8: Rahul Sharma | D8: Barcode Scanner | E8: Warehouse Equipment | F8: Siam Components | G8: India | H8: Vietnam | I8: Vietnam | J8: Singapore Hub | K8: Rail | L8: 457 | M8: 180 | N8: 82260 | O8: 325 | P8: 125 | Q8: 8 | R8: 46230 | S8: 46230 | T8: On Time | U8: =VSCN_Clean[[#This Row],[Delivery Date]]-VSCN_Clean[[#This Row],[Promised Date]] -> 0 | V8: =--(VSCN_Clean[[#This Row],[Delivery Date]]<=VSCN_Clean[[#This Row],[Promised Date]]) -> 1 | W8: =--(VSCN_Clean[[#This Row],[Delivery Date]]>VSCN_Clean[[#This Row],[Promised Date]]) -> 0 | X8: =IF(VSCN_Clean[[#This Row],[Current Stock]]<=0,"Stock-out",IF(VSCN_Clean[[#This Row],[Current Stock]]<VSCN_Clean[[#This Row],[Reorder Level]],"Low Stock","Healthy")) -> Healthy | Y8: =--(VSCN_Clean[[#This Row],[Current Stock]]<=0) -> 0 | Z8: =--(AND(VSCN_Clean[[#This Row],[Current Stock]]>0,VSCN_Clean[[#This Row],[Current Stock]]<VSCN_Clean[[#This Row],[Reorder Level]])) -> 0 | AA8: =--(VSCN_Clean[[#This Row],[Current Stock]]>=VSCN_Clean[[#This Row],[Reorder Level]]) -> 1 | AB8: =IFERROR(COUNTIFS(VSCN_Clean[Supplier],VSCN_Clean[[#This Row],[Supplier]],VSCN_Clean[On-Time Flag],1)/COUNTIF(VSCN_Clean[Supplier],VSCN_Clean[[#This Row],[Supplier]]),0) -> 1 | AC8: =VSCN_Clean[[#This Row],[Delivery Date]]-VSCN_Clean[[#This Row],[Order Date]] -> 8 | AD8: =VSCN_Clean[[#This Row],[Current Stock]]-VSCN_Clean[[#This Row],[Reorder Level]] -> 200
A9: SC-1008 | B9: 46227 | C9: Ananya Iyer | D9: RFID Labels | E9: Technology | F9: Pacific Source | G9: India | H9: Vietnam | I9: Vietnam | J9: Mumbai DC | K9: Air | L9: 127 | M9: 0.8 | N9: 101.6 | O9: 83 | P9: 75 | Q9: 10 | R9: 46237 | S9: 46238 | T9: Delayed | U9: =VSCN_Clean[[#This Row],[Delivery Date]]-VSCN_Clean[[#This Row],[Promised Date]] -> 1 | V9: =--(VSCN_Clean[[#This Row],[Delivery Date]]<=VSCN_Clean[[#This Row],[Promised Date]]) -> 0 | W9: =--(VSCN_Clean[[#This Row],[Delivery Date]]>VSCN_Clean[[#This Row],[Promised Date]]) -> 1 | X9: =IF(VSCN_Clean[[#This Row],[Current Stock]]<=0,"Stock-out",IF(VSCN_Clean[[#This Row],[Current Stock]]<VSCN_Clean[[#This Row],[Reorder Level]],"Low Stock","Healthy")) -> Healthy | Y9: =--(VSCN_Clean[[#This Row],[Current Stock]]<=0) -> 0 | Z9: =--(AND(VSCN_Clean[[#This Row],[Current Stock]]>0,VSCN_Clean[[#This Row],[Current Stock]]<VSCN_Clean[[#This Row],[Reorder Level]])) -> 0 | AA9: =--(VSCN_Clean[[#This Row],[Current Stock]]>=VSCN_Clean[[#This Row],[Reorder Level]]) -> 1 | AB9: =IFERROR(COUNTIFS(VSCN_Clean[Supplier],VSCN_Clean[[#This Row],[Supplier]],VSCN_Clean[On-Time Flag],1)/COUNTIF(VSCN_Clean[Supplier],VSCN_Clean[[#This Row],[Supplier]]),0) -> 0.6 | AC9: =VSCN_Clean[[#This Row],[Delivery Date]]-VSCN_Clean[[#This Row],[Order Date]] -> 11 | AD9: =VSCN_Clean[[#This Row],[Current Stock]]-VSCN_Clean[[#This Row],[Reorder Level]] -> 8
A10: SC-1009 | B10: 46221 | C10: Tan Wei Ming | D10: Safety Helmet | E10: Safety | F10: IndoTrade Solutions | G10: Vietnam | H10: Singapore | I10: Singapore | J10: Hanoi DC | K10: Air | L10: 132 | M10: 18 | N10: 2376 | O10: 205 | P10: 100 | Q10: 7 | R10: 46228 | S10: 46228 | T10: On Time | U10: =VSCN_Clean[[#This Row],[Delivery Date]]-VSCN_Clean[[#This Row],[Promised Date]] -> 0 | V10: =--(VSCN_Clean[[#This Row],[Delivery Date]]<=VSCN_Clean[[#This Row],[Promised Date]]) -> 1 | W10: =--(VSCN_Clean[[#This Row],[Delivery Date]]>VSCN_Clean[[#This Row],[Promised Date]]) -> 0 | X10: =IF(VSCN_Clean[[#This Row],[Current Stock]]<=0,"Stock-out",IF(VSCN_Clean[[#This Row],[Current Stock]]<VSCN_Clean[[#This Row],[Reorder Level]],"Low Stock","Healthy")) -> Healthy | Y10: =--(VSCN_Clean[[#This Row],[Current Stock]]<=0) -> 0 | Z10: =--(AND(VSCN_Clean[[#This Row],[Current Stock]]>0,VSCN_Clean[[#This Row],[Current Stock]]<VSCN_Clean[[#This Row],[Reorder Level]])) -> 0 | AA10: =--(VSCN_Clean[[#This Row],[Current Stock]]>=VSCN_Clean[[#This Row],[Reorder Level]]) -> 1 | AB10: =IFERROR(COUNTIFS(VSCN_Clean[Supplier],VSCN_Clean[[#This Row],[Supplier]],VSCN_Clean[On-Time Flag],1)/COUNTIF(VSCN_Clean[Supplier],VSCN_Clean[[#This Row],[Supplier]]),0) -> 0.75 | AC10: =VSCN_Clean[[#This Row],[Delivery Date]]-VSCN_Clean[[#This Row],[Order Date]] -> 7 | AD10: =VSCN_Clean[[#This Row],[Current Stock]]-VSCN_Clean[[#This Row],[Reorder Level]] -> 105
A11: SC-1010 | B11: 46217 | C11: Lim Jia Hui | D11: Conveyor Belt | E11: Material Handling | F11: IndoTrade Solutions | G11: Malaysia | H11: Vietnam | I11: Vietnam | J11: Bangkok DC | K11: Rail | L11: 468 | M11: 420 | N11: 196560 | O11: 73 | P11: 125 | Q11: 7 | R11: 46224 | S11: 46224 | T11: On Time | U11: =VSCN_Clean[[#This Row],[Delivery Date]]-VSCN_Clean[[#This Row],[Promised Date]] -> 0 | V11: =--(VSCN_Clean[[#This Row],[Delivery Date]]<=VSCN_Clean[[#This Row],[Promised Date]]) -> 1 | W11: =--(VSCN_Clean[[#This Row],[Delivery Date]]>VSCN_Clean[[#This Row],[Promised Date]]) -> 0 | X11: =IF(VSCN_Clean[[#This Row],[Current Stock]]<=0,"Stock-out",IF(VSCN_Clean[[#This Row],[Current Stock]]<VSCN_Clean[[#This Row],[Reorder Level]],"Low Stock","Healthy")) -> Low Stock | Y11: =--(VSCN_Clean[[#This Row],[Current Stock]]<=0) -> 0 | Z11: =--(AND(VSCN_Clean[[#This Row],[Current Stock]]>0,VSCN_Clean[[#This Row],[Current Stock]]<VSCN_Clean[[#This Row],[Reorder Level]])) -> 1 | AA11: =--(VSCN_Clean[[#This Row],[Current Stock]]>=VSCN_Clean[[#This Row],[Reorder Level]]) -> 0 | AB11: =IFERROR(COUNTIFS(VSCN_Clean[Supplier],VSCN_Clean[[#This Row],[Supplier]],VSCN_Clean[On-Time Flag],1)/COUNTIF(VSCN_Clean[Supplier],VSCN_Clean[[#This Row],[Supplier]]),0) -> 0.75 | AC11: =VSCN_Clean[[#This Row],[Delivery Date]]-VSCN_Clean[[#This Row],[Order Date]] -> 7 | AD11: =VSCN_Clean[[#This Row],[Current Stock]]-VSCN_Clean[[#This Row],[Reorder Level]] -> -52
A12: SC-1011 | B12: 46219 | C12: Siti Nur Aisyah | D12: Safety Helmet | E12: Safety | F12: Pacific Source | G12: India | H12: Singapore | I12: Singapore | J12: Mumbai DC | K12: Rail | L12: 295 | M12: 18 | N12: 5310 | O12: 185 | P12: 125 | Q12: 6 | R12: 46225 | S12: 46225 | T12: On Time | U12: =VSCN_Clean[[#This Row],[Delivery Date]]-VSCN_Clean[[#This Row],[Promised Date]] -> 0 | V12: =--(VSCN_Clean[[#This Row],[Delivery Date]]<=VSCN_Clean[[#This Row],[Promised Date]]) -> 1 | W12: =--(VSCN_Clean[[#This Row],[Delivery Date]]>VSCN_Clean[[#This Row],[Promised Date]]) -> 0 | X12: =IF(VSCN_Clean[[#This Row],[Current Stock]]<=0,"Stock-out",IF(VSCN_Clean[[#This Row],[Current Stock]]<VSCN_Clean[[#This Row],[Reorder Level]],"Low Stock","Healthy")) -> Healthy | Y12: =--(VSCN_Clean[[#This Row],[Current Stock]]<=0) -> 0 | Z12: =--(AND(VSCN_Clean[[#This Row],[Current Stock]]>0,VSCN_Clean[[#This Row],[Current Stock]]<VSCN_Clean[[#This Row],[Reorder Level]])) -> 0 | AA12: =--(VSCN_Clean[[#This Row],[Current Stock]]>=VSCN_Clean[[#This Row],[Reorder Level]]) -> 1 | AB12: =IFERROR(COUNTIFS(VSCN_Clean[Supplier],VSCN_Clean[[#This Row],[Supplier]],VSCN_Clean[On-Time Flag],1)/COUNTIF(VSCN_Clean[Supplier],VSCN_Clean[[#This Row],[Supplier]]),0) -> 0.6 | AC12: =VSCN_Clean[[#This Row],[Delivery Date]]-VSCN_Clean[[#This Row],[Order Date]] -> 6 | AD12: =VSCN_Clean[[#This Row],[Current Stock]]-VSCN_Clean[[#This Row],[Reorder Level]] -> 60
A13: SC-1012 | B13: 46236 | C13: Ahmad Faiz | D13: Stretch Film | E13: Packaging | F13: VinaTech Supplies | G13: India | H13: Vietnam | I13: Vietnam | J13: Kuala Lumpur DC | K13: Air | L13: 66 | M13: 15 | N13: 990 | O13: 348 | P13: 75 | Q13: 9 | R13: 46245 | S13: 46247 | T13: Delayed | U13: =VSCN_Clean[[#This Row],[Delivery Date]]-VSCN_Clean[[#This Row],[Promised Date]] -> 2 | V13: =--(VSCN_Clean[[#This Row],[Delivery Date]]<=VSCN_Clean[[#This Row],[Promised Date]]) -> 0 | W13: =--(VSCN_Clean[[#This Row],[Delivery Date]]>VSCN_Clean[[#This Row],[Promised Date]]) -> 1 | X13: =IF(VSCN_Clean[[#This Row],[Current Stock]]<=0,"Stock-out",IF(VSCN_Clean[[#This Row],[Current Stock]]<VSCN_Clean[[#This Row],[Reorder Level]],"Low Stock","Healthy")) -> Healthy | Y13: =--(VSCN_Clean[[#This Row],[Current Stock]]<=0) -> 0 | Z13: =--(AND(VSCN_Clean[[#This Row],[Current Stock]]>0,VSCN_Clean[[#This Row],[Current Stock]]<VSCN_Clean[[#This Row],[Reorder Level]])) -> 0 | AA13: =--(VSCN_Clean[[#This Row],[Current Stock]]>=VSCN_Clean[[#This Row],[Reorder Level]]) -> 1 | AB13: =IFERROR(COUNTIFS(VSCN_Clean[Supplier],VSCN_Clean[[#This Row],[Supplier]],VSCN_Clean[On-Time Flag],1)/COUNTIF(VSCN_Clean[Supplier],VSCN_Clean[[#This Row],[Supplier]]),0) -> 0.25 | AC13: =VSCN_Clean[[#This Row],[Delivery Date]]-VSCN_Clean[[#This Row],[Order Date]] -> 11 | AD13: =VSCN_Clean[[#This Row],[Current Stock]]-VSCN_Clean[[#This Row],[Reorder Level]] -> 273
... A31: SC-1030 | B31: 46242 | C31: Dimas Pratama | D31: Barcode Scanner | E31: Warehouse Equipment | F31: Siam Components | G31: Indonesia | H31: Thailand | I31: Thailand | J31: Mumbai DC | K31: Sea | L31: 365 | M31: 180 | N31: 65700 | O31: 296 | P31: 75 | Q31: 12 | R31: 46254 | S31: 46254 | T31: On Time | U31: =VSCN_Clean[[#This Row],[Delivery Date]]-VSCN_Clean[[#This Row],[Promised Date]] -> 0 | V31: =--(VSCN_Clean[[#This Row],[Delivery Date]]<=VSCN_Clean[[#This Row],[Promised Date]]) -> 1 | W31: =--(VSCN_Clean[[#This Row],[Delivery Date]]>VSCN_Clean[[#This Row],[Promised Date]]) -> 0 | X31: =IF(VSCN_Clean[[#This Row],[Current Stock]]<=0,"Stock-out",IF(VSCN_Clean[[#This Row],[Current Stock]]<VSCN_Clean[[#This Row],[Reorder Level]],"Low Stock","Healthy")) -> Healthy | Y31: =--(VSCN_Clean[[#This Row],[Current Stock]]<=0) -> 0 | Z31: =--(AND(VSCN_Clean[[#This Row],[Current Stock]]>0,VSCN_Clean[[#This Row],[Current Stock]]<VSCN_Clean[[#This Row],[Reorder Level]])) -> 0 | AA31: =--(VSCN_Clean[[#This Row],[Current Stock]]>=VSCN_Clean[[#This Row],[Reorder Level]]) -> 1 | AB31: =IFERROR(COUNTIFS(VSCN_Clean[Supplier],VSCN_Clean[[#This Row],[Supplier]],VSCN_Clean[On-Time Flag],1)/COUNTIF(VSCN_Clean[Supplier],VSCN_Clean[[#This Row],[Supplier]]),0) -> 1 | AC31: =VSCN_Clean[[#This Row],[Delivery Date]]-VSCN_Clean[[#This Row],[Order Date]] -> 12 | AD31: =VSCN_Clean[[#This Row],[Current Stock]]-VSCN_Clean[[#This Row],[Reorder Level]] -> 221

Sheet Data Quality Audit
A1: Supply Chain Data Quality Audit
A2: Source preserved unchanged; cleaned analysis copy created from all 30 records.
A4: Validation Check | B4: Records Checked | C4: Issues Found | D4: Result | E4: Action Taken | F4: Correction Needed
A5: Blank required fields | B5: 30 | C5: 0 | D5: Pass | E5: None | F5: No
A6: Duplicate Order IDs | B6: 30 | C6: 0 | D6: Pass | E6: None | F6: No
A7: Fully duplicate records | B7: 30 | C7: 0 | D7: Pass | E7: None | F7: No
A8: Order / Promised / Delivery dates | B8: 30 | C8: 0 | D8: Pass | E8: Standardized display to dd-mmm-yyyy in clean copy | F8: No
A9: Numeric field types | B9: 30 | C9: 0 | D9: Pass | E9: Standardized integer and decimal formats in clean copy | F9: No
A10: Order Value = Quantity × Unit Cost | B10: 30 | C10: 0 | D10: Pass | E10: None | F10: No
A11: Promised Date = Order Date + Lead Time | B11: 30 | C11: 0 | D11: Pass | E11: None | F11: No
A12: Delivery Status vs promised date | B12: 30 | C12: 0 | D12: Pass | E12: None | F12: No
A13: Region matches Destination | B13: 30 | C13: 0 | D13: Pass | E13: None | F13: No
A14: Categorical label consistency | B14: 30 | C14: 0 | D14: Pass | E14: No label changes required | F14: No
A17: Field | B17: Distinct Values | C17: Validated Labels
A18: Category | B18: 6 | C18: Electronics; Material Handling; Packaging; Safety; Technology; Warehouse Equipment
A19: Supplier | B19: 10 | C19: AsiaLogix; Dragon Supply Co.; Horizon Packaging; IndoTrade Solutions; Korea Industrial Co.; Mekong Distribution; Nippon Industrial; Pacific Source; Siam Components; VinaTech Supplies
A20: Region | B20: 5 | C20: Malaysia; Philippines; Singapore; Thailand; Vietnam
A21: Warehouse | B21: 6 | C21: Bangkok DC; Hanoi DC; Ho Chi Minh DC; Kuala Lumpur DC; Mumbai DC; Singapore Hub
A22: Transport Mode | B22: 4 | C22: Air; Rail; Road; Sea
A23: Delivery Status | B23: 2 | C23: Delayed; On Time
A26: Observation | B26: Assessment
A27: Source date cells are already true Excel dates | B27: Only their display format required standardization in the clean copy.
A28: All six requested numeric fields contain numeric values | B28: All values are non-negative; Quantity and stock/lead-time fields are whole numbers.
A29: No corrections to source values were made | B29: The original `VSCN_DataSet` remains intact on Sheet1.
A30: Operational alert (not a data-quality error) | B30: 10 records have Current Stock below Reorder Level (SC-1003, SC-1006, SC-1010, SC-1014, SC-1017, SC-1020, SC-1021, SC-1025, SC-1026, SC-1029); review during analysis.

Sheet KPI Framework
A1: Supply Chain Management KPI Framework
A2: Current performance, calculation logic, and final-dashboard priorities based on all 30 cleaned orders
A4: Priority | B4: KPI | C4: Current Value | D4: Calculation | E4: Why It Matters | F4: Final Dashboard | G4: Management Interpretation
A5: 1 | B5: On-Time Delivery % | C5: =AVERAGE(VSCN_Clean[On-Time Flag]) -> 0.6 | D5: On-time orders ÷ total orders | E5: Primary customer-service and logistics reliability measure. | F5: Recommended | G5: 60.0% indicates substantial delivery reliability risk.
A6: 2 | B6: Delayed Orders | C6: =SUM(VSCN_Clean[Delay Flag]) -> 12 | D6: Count of orders marked Delayed | E6: Shows the immediate exception workload requiring corrective action. | F6: Recommended | G6: 12 orders require delay root-cause review.
A7: 3 | B7: Total Order Value | C7: =SUM(VSCN_Clean[Order Value]) -> 1004846.1 | D7: Sum of Order Value | E7: Quantifies financial exposure, throughput, and supplier spend under management. | F7: Recommended | G7: Over 1.00M of order value is represented in the current dataset.
A8: 4 | B8: Low Stock Items | C8: =SUM(VSCN_Clean[Low Stock Flag]) -> 10 | D8: Current Stock > 0 and below Reorder Level | E8: Identifies replenishment risk before a full stock-out occurs. | F8: Recommended | G8: 10 orders are below their reorder thresholds.
A9: 5 | B9: Stock-out Orders | C9: =SUM(VSCN_Clean[Stock-out Flag]) -> 0 | D9: Count where Current Stock ≤ 0 | E9: Signals immediate inability to fulfill demand and potential lost sales. | F9: Recommended | G9: No current stock-outs; retain as a critical exception KPI.
A10: 6 | B10: Supplier Performance | C10: =COUNTIF(D19:D28,">=90%")&" of "&COUNTA(A19:A28)&" suppliers ≥90%" -> 2 of 10 suppliers ≥90% | D10: Suppliers with ≥90% on-time delivery | E10: Supports supplier reviews, sourcing allocation, and corrective action. | F10: Recommended | G10: 2 of 10 suppliers currently meet a 90% on-time threshold.
A11: 7 | B11: Average Lead Time | C11: =AVERAGE(VSCN_Clean[Lead Time (Days)]) -> 9.1 | D11: Average of Lead Time (Days) | E11: Tracks replenishment responsiveness and informs safety-stock planning. | F11: Recommended | G11: Average lead time is 9.1 days.
A12: 8 | B12: Total Orders | C12: =COUNTA(VSCN_Clean[Order ID]) -> 30 | D12: Count of unique Order IDs | E12: Provides the workload denominator for service and exception rates. | F12: Recommended | G12: 30 orders form the current reporting base.
A13: 9 | B13: Total Quantity | C13: =SUM(VSCN_Clean[Quantity]) -> 6751 | D13: Sum of Quantity | E13: Measures physical volume for capacity and transportation planning. | F13: Secondary | G13: 6,751 units; useful as context but less decision-oriented alone.
A14: 10 | B14: Healthy Stock Items | C14: =SUM(VSCN_Clean[Healthy Stock Flag]) -> 20 | D14: Current Stock at or above Reorder Level | E14: Shows the share of inventory currently outside replenishment risk. | F14: Secondary | G14: 20 orders are at or above reorder level.
A17: Supplier Performance Detail
A18: Supplier | B18: Orders | C18: On-Time Orders | D18: On-Time % | E18: Delayed Orders | F18: Order Value | G18: Avg Lead Time
A19: AsiaLogix | B19: =COUNTIF(VSCN_Clean[Supplier],A19) -> 1 | C19: =COUNTIFS(VSCN_Clean[Supplier],A19,VSCN_Clean[Delivery Status],"On Time") -> 0 | D19: =IFERROR(C19/B19,0) -> 0 | E19: =COUNTIFS(VSCN_Clean[Supplier],A19,VSCN_Clean[Delivery Status],"Delayed") -> 1 | F19: =SUMIF(VSCN_Clean[Supplier],A19,VSCN_Clean[Order Value]) -> 89050 | G19: =AVERAGEIF(VSCN_Clean[Supplier],A19,VSCN_Clean[Lead Time (Days)]) -> 7
A20: Dragon Supply Co. | B20: =COUNTIF(VSCN_Clean[Supplier],A20) -> 3 | C20: =COUNTIFS(VSCN_Clean[Supplier],A20,VSCN_Clean[Delivery Status],"On Time") -> 3 | D20: =IFERROR(C20/B20,0) -> 1 | E20: =COUNTIFS(VSCN_Clean[Supplier],A20,VSCN_Clean[Delivery Status],"Delayed") -> 0 | F20: =SUMIF(VSCN_Clean[Supplier],A20,VSCN_Clean[Order Value]) -> 101110 | G20: =AVERAGEIF(VSCN_Clean[Supplier],A20,VSCN_Clean[Lead Time (Days)]) -> 10.666667
A21: Horizon Packaging | B21: =COUNTIF(VSCN_Clean[Supplier],A21) -> 2 | C21: =COUNTIFS(VSCN_Clean[Supplier],A21,VSCN_Clean[Delivery Status],"On Time") -> 1 | D21: =IFERROR(C21/B21,0) -> 0.5 | E21: =COUNTIFS(VSCN_Clean[Supplier],A21,VSCN_Clean[Delivery Status],"Delayed") -> 1 | F21: =SUMIF(VSCN_Clean[Supplier],A21,VSCN_Clean[Order Value]) -> 6228 | G21: =AVERAGEIF(VSCN_Clean[Supplier],A21,VSCN_Clean[Lead Time (Days)]) -> 6
A22: IndoTrade Solutions | B22: =COUNTIF(VSCN_Clean[Supplier],A22) -> 4 | C22: =COUNTIFS(VSCN_Clean[Supplier],A22,VSCN_Clean[Delivery Status],"On Time") -> 3 | D22: =IFERROR(C22/B22,0) -> 0.75 | E22: =COUNTIFS(VSCN_Clean[Supplier],A22,VSCN_Clean[Delivery Status],"Delayed") -> 1 | F22: =SUMIF(VSCN_Clean[Supplier],A22,VSCN_Clean[Order Value]) -> 367916 | G22: =AVERAGEIF(VSCN_Clean[Supplier],A22,VSCN_Clean[Lead Time (Days)]) -> 7
A23: Korea Industrial Co. | B23: =COUNTIF(VSCN_Clean[Supplier],A23) -> 3 | C23: =COUNTIFS(VSCN_Clean[Supplier],A23,VSCN_Clean[Delivery Status],"On Time") -> 1 | D23: =IFERROR(C23/B23,0) -> 0.33333333 | E23: =COUNTIFS(VSCN_Clean[Supplier],A23,VSCN_Clean[Delivery Status],"Delayed") -> 2 | F23: =SUMIF(VSCN_Clean[Supplier],A23,VSCN_Clean[Order Value]) -> 75564 | G23: =AVERAGEIF(VSCN_Clean[Supplier],A23,VSCN_Clean[Lead Time (Days)]) -> 11.666667
A24: Mekong Distribution | B24: =COUNTIF(VSCN_Clean[Supplier],A24) -> 1 | C24: =COUNTIFS(VSCN_Clean[Supplier],A24,VSCN_Clean[Delivery Status],"On Time") -> 0 | D24: =IFERROR(C24/B24,0) -> 0 | E24: =COUNTIFS(VSCN_Clean[Supplier],A24,VSCN_Clean[Delivery Status],"Delayed") -> 1 | F24: =SUMIF(VSCN_Clean[Supplier],A24,VSCN_Clean[Order Value]) -> 1737 | G24: =AVERAGEIF(VSCN_Clean[Supplier],A24,VSCN_Clean[Lead Time (Days)]) -> 15
A25: Nippon Industrial | B25: =COUNTIF(VSCN_Clean[Supplier],A25) -> 3 | C25: =COUNTIFS(VSCN_Clean[Supplier],A25,VSCN_Clean[Delivery Status],"On Time") -> 2 | D25: =IFERROR(C25/B25,0) -> 0.66666667 | E25: =COUNTIFS(VSCN_Clean[Supplier],A25,VSCN_Clean[Delivery Status],"Delayed") -> 1 | F25: =SUMIF(VSCN_Clean[Supplier],A25,VSCN_Clean[Order Value]) -> 11244 | G25: =AVERAGEIF(VSCN_Clean[Supplier],A25,VSCN_Clean[Lead Time (Days)]) -> 6.6666667
A26: Pacific Source | B26: =COUNTIF(VSCN_Clean[Supplier],A26) -> 5 | C26: =COUNTIFS(VSCN_Clean[Supplier],A26,VSCN_Clean[Delivery Status],"On Time") -> 3 | D26: =IFERROR(C26/B26,0) -> 0.6 | E26: =COUNTIFS(VSCN_Clean[Supplier],A26,VSCN_Clean[Delivery Status],"Delayed") -> 2 | F26: =SUMIF(VSCN_Clean[Supplier],A26,VSCN_Clean[Order Value]) -> 20176.1 | G26: =AVERAGEIF(VSCN_Clean[Supplier],A26,VSCN_Clean[Lead Time (Days)]) -> 8.8
A27: Siam Components | B27: =COUNTIF(VSCN_Clean[Supplier],A27) -> 4 | C27: =COUNTIFS(VSCN_Clean[Supplier],A27,VSCN_Clean[Delivery Status],"On Time") -> 4 | D27: =IFERROR(C27/B27,0) -> 1 | E27: =COUNTIFS(VSCN_Clean[Supplier],A27,VSCN_Clean[Delivery Status],"Delayed") -> 0 | F27: =SUMIF(VSCN_Clean[Supplier],A27,VSCN_Clean[Order Value]) -> 192995 | G27: =AVERAGEIF(VSCN_Clean[Supplier],A27,VSCN_Clean[Lead Time (Days)]) -> 10
A28: VinaTech Supplies | B28: =COUNTIF(VSCN_Clean[Supplier],A28) -> 4 | C28: =COUNTIFS(VSCN_Clean[Supplier],A28,VSCN_Clean[Delivery Status],"On Time") -> 1 | D28: =IFERROR(C28/B28,0) -> 0.25 | E28: =COUNTIFS(VSCN_Clean[Supplier],A28,VSCN_Clean[Delivery Status],"Delayed") -> 3 | F28: =SUMIF(VSCN_Clean[Supplier],A28,VSCN_Clean[Order Value]) -> 138826 | G28: =AVERAGEIF(VSCN_Clean[Supplier],A28,VSCN_Clean[Lead Time (Days)]) -> 10
A30: Definitions: Stock-out = Current Stock ≤ 0. Low Stock = Current Stock > 0 but below Reorder Level. Healthy Stock = Current Stock ≥ Reorder Level. Supplier target = ≥90% on-time delivery; interpret small supplier samples cautiously.
A32: Calculated Field Dictionary
A33: Calculated Field | B33: Table Formula Logic | C33: Output | D33: Analytical Use
A34: Delivery Delay Days | B34: Delivery Date − Promised Date | C34: Days; positive = late | D34: Measures lateness severity, not just delay frequency.
A35: On-Time Flag | B35: 1 when Delivery Date ≤ Promised Date; otherwise 0 | C35: 36526 | D35: Average produces On-Time Delivery %.
A36: Delay Flag | B36: 1 when Delivery Date > Promised Date; otherwise 0 | C36: 36526 | D36: Sum produces Delayed Orders.
A37: Stock Status | B37: Stock-out if stock ≤ 0; Low Stock if below reorder level; otherwise Healthy | C37: Text category | D37: Supports clear inventory exception segmentation.
A38: Stock-out Flag | B38: 1 when Current Stock ≤ 0 | C38: 36526 | D38: Sum produces Stock-out Orders.
A39: Low Stock Flag | B39: 1 when stock is positive but below Reorder Level | C39: 36526 | D39: Sum produces Low Stock Items without double-counting stock-outs.
A40: Healthy Stock Flag | B40: 1 when Current Stock ≥ Reorder Level | C40: 36526 | D40: Sum produces Healthy Stock Items.
A41: Supplier On-Time % | B41: Supplier on-time orders ÷ all orders for that supplier | C41: Percentage | D41: Compares delivery reliability across suppliers.
A42: Delivery Cycle Days | B42: Delivery Date − Order Date | C42: Days | D42: Shows actual end-to-end fulfillment duration.
A43: Stock Variance | B43: Current Stock − Reorder Level | C43: Units | D43: Quantifies inventory surplus or replenishment shortfall.

Sheet Dashboard Pivots
A5: Total Orders | B5: Total Order Value | C5: On-Time Delivery % | D5: Delayed Orders | E5: Average Lead Time | F5: Stock-out Orders | G5: Low Stock Items
A6: 30 | B6: 1004846.1 | C6: 0.6 | D6: 12 | E6: 9.1 | F6: 0 | G6: 10
A15: Delivery Status | B15: Orders
A16: Delayed | B16: 12
A17: On Time | B17: 18
A18: Grand Total | B18: 30
A30: Supplier | B30: On-Time %
A31: AsiaLogix | B31: 0
A32: Dragon Supply Co. | B32: 1
A33: Horizon Packaging | B33: 0.5
A34: IndoTrade Solutions | B34: 0.75
A35: Korea Industrial Co. | B35: 0.33333333
A36: Mekong Distribution | B36: 0
A37: Nippon Industrial | B37: 0.66666667
A38: Pacific Source | B38: 0.6
A39: Siam Components | B39: 1
A40: VinaTech Supplies | B40: 0.25
A41: Grand Total | B41: 0.6
A50: Category | B50: Order Value
A51: Electronics | B51: 470670
A52: Material Handling | B52: 295680
A53: Packaging | B53: 7276.5
A54: Safety | B54: 38682
A55: Technology | B55: 101.6
A56: Warehouse Equipment | B56: 192436
A57: Grand Total | B57: 1004846.1
A65: Stock Status | B65: Orders
A66: Healthy | B66: 20
A67: Low Stock | B67: 10
A68: Grand Total | B68: 30
A80: Transport Mode | B80: Order Value
A81: Air | B81: 230683.6
A82: Rail | B82: 400052
A83: Road | B83: 186186.5
A84: Sea | B84: 187924
A85: Grand Total | B85: 1004846.1
A95: Region | B95: On-Time %
A96: Malaysia | B96: 0.75
A97: Philippines | B97: 1
A98: Singapore | B98: 0.625
...

Sheet Executive Dashboard
A1: Executive Supply Chain Analytics Dashboard
A3: Management view of delivery reliability, inventory exposure, supplier performance, and order value | 30 cleaned orders
A5: Total Orders | E5: Total Order Value | I5: On-Time Delivery % | M5: Delayed Orders | Q5: Average Lead Time | U5: Stock-out / Low Stock
A6: ='Dashboard Pivots'!A6 -> 30 | E6: ='Dashboard Pivots'!B6 -> 1004846.1 | I6: ='Dashboard Pivots'!C6 -> 0.6 | M6: ='Dashboard Pivots'!D6 -> 12 | Q6: ='Dashboard Pivots'!E6 -> 9.1 | U6: ='Dashboard Pivots'!F6&" / "&'Dashboard Pivots'!G6 -> 0 / 10
A8: Current reporting volume | E8: Financial exposure | I8: Target: ≥90% | M8: Orders requiring review | Q8: Days from order to promise | U8: Immediate / emerging risk
A10: Delivery, Supplier & Order Value Performance
A27: Inventory Risk & Network Performance
A44: Interactive View Filters
